{"asctime": "[2023-07-05 09:21:51 +0800]", "process": 18232, "levelname": "ERROR", "message": "Experienced exception while trying to serve", "exc_info": "Traceback (most recent call last):\n  File \"D:\\environment\\Anaconda3\\envs\\cv\\Lib\\site-packages\\sanic\\mixins\\startup.py\", line 853, in serve\n    manager.run()\n  File \"D:\\environment\\Anaconda3\\envs\\cv\\Lib\\site-packages\\sanic\\worker\\manager.py\", line 122, in run\n    self.monitor()\n  File \"D:\\environment\\Anaconda3\\envs\\cv\\Lib\\site-packages\\sanic\\worker\\manager.py\", line 183, in monitor\n    self.wait_for_ack()\n  File \"D:\\environment\\Anaconda3\\envs\\cv\\Lib\\site-packages\\sanic\\worker\\manager.py\", line 240, in wait_for_ack\n    if self.monitor_subscriber.poll(0.1):\n       ^^^^^^^^^^^^^^^^^^^^^^^^^^^^^^^^^\n  File \"D:\\environment\\Anaconda3\\envs\\cv\\Lib\\multiprocessing\\connection.py\", line 256, in poll\n    return self._poll(timeout)\n           ^^^^^^^^^^^^^^^^^^^\n  File \"D:\\environment\\Anaconda3\\envs\\cv\\Lib\\multiprocessing\\connection.py\", line 329, in _poll\n    return bool(wait([self], timeout))\n                ^^^^^^^^^^^^^^^^^^^^^\n  File \"D:\\environment\\Anaconda3\\envs\\cv\\Lib\\multiprocessing\\connection.py\", line 878, in wait\n    ready_handles = _exhaustive_wait(waithandle_to_obj.keys(), timeout)\n                    ^^^^^^^^^^^^^^^^^^^^^^^^^^^^^^^^^^^^^^^^^^^^^^^^^^^\n  File \"D:\\environment\\Anaconda3\\envs\\cv\\Lib\\multiprocessing\\connection.py\", line 810, in _exhaustive_wait\n    res = _winapi.WaitForMultipleObjects(L, False, timeout)\n          ^^^^^^^^^^^^^^^^^^^^^^^^^^^^^^^^^^^^^^^^^^^^^^^^^\nInterruptedError: [Errno 4] Interrupted function call"}
{"asctime": "[2023-07-05 09:22:45 +0800]", "process": 20108, "levelname": "ERROR", "message": "Experienced exception while trying to serve", "exc_info": "Traceback (most recent call last):\n  File \"D:\\environment\\Anaconda3\\envs\\cv\\Lib\\site-packages\\sanic\\mixins\\startup.py\", line 754, in serve\n    for sock in [\n                ^\n  File \"D:\\environment\\Anaconda3\\envs\\cv\\Lib\\site-packages\\sanic\\mixins\\startup.py\", line 755, in <listcomp>\n    configure_socket(server_info.settings)\n  File \"D:\\environment\\Anaconda3\\envs\\cv\\Lib\\site-packages\\sanic\\server\\socket.py\", line 110, in configure_socket\n    sock = bind_socket(\n           ^^^^^^^^^^^^\n  File \"D:\\environment\\Anaconda3\\envs\\cv\\Lib\\site-packages\\sanic\\server\\socket.py\", line 33, in bind_socket\n    sock.bind(location)\nTypeError: 'str' object cannot be interpreted as an integer"}
{"asctime": "[2023-07-05 09:28:39 +0800]", "process": 4180, "levelname": "ERROR", "message": "Experienced exception while trying to serve", "exc_info": "Traceback (most recent call last):\n  File \"D:\\environment\\Anaconda3\\envs\\cv\\Lib\\site-packages\\sanic\\mixins\\startup.py\", line 853, in serve\n    manager.run()\n  File \"D:\\environment\\Anaconda3\\envs\\cv\\Lib\\site-packages\\sanic\\worker\\manager.py\", line 122, in run\n    self.monitor()\n  File \"D:\\environment\\Anaconda3\\envs\\cv\\Lib\\site-packages\\sanic\\worker\\manager.py\", line 183, in monitor\n    self.wait_for_ack()\n  File \"D:\\environment\\Anaconda3\\envs\\cv\\Lib\\site-packages\\sanic\\worker\\manager.py\", line 240, in wait_for_ack\n    if self.monitor_subscriber.poll(0.1):\n       ^^^^^^^^^^^^^^^^^^^^^^^^^^^^^^^^^\n  File \"D:\\environment\\Anaconda3\\envs\\cv\\Lib\\multiprocessing\\connection.py\", line 256, in poll\n    return self._poll(timeout)\n           ^^^^^^^^^^^^^^^^^^^\n  File \"D:\\environment\\Anaconda3\\envs\\cv\\Lib\\multiprocessing\\connection.py\", line 329, in _poll\n    return bool(wait([self], timeout))\n                ^^^^^^^^^^^^^^^^^^^^^\n  File \"D:\\environment\\Anaconda3\\envs\\cv\\Lib\\multiprocessing\\connection.py\", line 878, in wait\n    ready_handles = _exhaustive_wait(waithandle_to_obj.keys(), timeout)\n                    ^^^^^^^^^^^^^^^^^^^^^^^^^^^^^^^^^^^^^^^^^^^^^^^^^^^\n  File \"D:\\environment\\Anaconda3\\envs\\cv\\Lib\\multiprocessing\\connection.py\", line 810, in _exhaustive_wait\n    res = _winapi.WaitForMultipleObjects(L, False, timeout)\n          ^^^^^^^^^^^^^^^^^^^^^^^^^^^^^^^^^^^^^^^^^^^^^^^^^\nInterruptedError: [Errno 4] Interrupted function call"}
{"asctime": "[2023-07-05 12:10:19 +0800]", "process": 22232, "levelname": "ERROR", "message": "Experienced exception while trying to serve", "exc_info": "Traceback (most recent call last):\n  File \"D:\\environment\\Anaconda3\\envs\\cv\\Lib\\site-packages\\sanic\\mixins\\startup.py\", line 754, in serve\n    for sock in [\n                ^\n  File \"D:\\environment\\Anaconda3\\envs\\cv\\Lib\\site-packages\\sanic\\mixins\\startup.py\", line 755, in <listcomp>\n    configure_socket(server_info.settings)\n  File \"D:\\environment\\Anaconda3\\envs\\cv\\Lib\\site-packages\\sanic\\server\\socket.py\", line 110, in configure_socket\n    sock = bind_socket(\n           ^^^^^^^^^^^^\n  File \"D:\\environment\\Anaconda3\\envs\\cv\\Lib\\site-packages\\sanic\\server\\socket.py\", line 33, in bind_socket\n    sock.bind(location)\nTypeError: 'str' object cannot be interpreted as an integer"}
{"asctime": "[2023-07-05 12:11:30 +0800]", "process": 26968, "levelname": "ERROR", "message": "Experienced exception while trying to serve", "exc_info": "Traceback (most recent call last):\n  File \"D:\\environment\\Anaconda3\\envs\\cv\\Lib\\site-packages\\sanic\\mixins\\startup.py\", line 754, in serve\n    for sock in [\n                ^\n  File \"D:\\environment\\Anaconda3\\envs\\cv\\Lib\\site-packages\\sanic\\mixins\\startup.py\", line 755, in <listcomp>\n    configure_socket(server_info.settings)\n  File \"D:\\environment\\Anaconda3\\envs\\cv\\Lib\\site-packages\\sanic\\server\\socket.py\", line 110, in configure_socket\n    sock = bind_socket(\n           ^^^^^^^^^^^^\n  File \"D:\\environment\\Anaconda3\\envs\\cv\\Lib\\site-packages\\sanic\\server\\socket.py\", line 33, in bind_socket\n    sock.bind(location)\nTypeError: 'str' object cannot be interpreted as an integer"}
{"asctime": "[2023-07-05 13:43:53 +0800]", "process": 24064, "levelname": "ERROR", "message": "Experienced exception while trying to serve", "exc_info": "Traceback (most recent call last):\n  File \"D:\\environment\\Anaconda3\\envs\\cv\\Lib\\site-packages\\sanic\\mixins\\startup.py\", line 853, in serve\n    manager.run()\n  File \"D:\\environment\\Anaconda3\\envs\\cv\\Lib\\site-packages\\sanic\\worker\\manager.py\", line 122, in run\n    self.monitor()\n  File \"D:\\environment\\Anaconda3\\envs\\cv\\Lib\\site-packages\\sanic\\worker\\manager.py\", line 183, in monitor\n    self.wait_for_ack()\n  File \"D:\\environment\\Anaconda3\\envs\\cv\\Lib\\site-packages\\sanic\\worker\\manager.py\", line 240, in wait_for_ack\n    if self.monitor_subscriber.poll(0.1):\n       ^^^^^^^^^^^^^^^^^^^^^^^^^^^^^^^^^\n  File \"D:\\environment\\Anaconda3\\envs\\cv\\Lib\\multiprocessing\\connection.py\", line 256, in poll\n    return self._poll(timeout)\n           ^^^^^^^^^^^^^^^^^^^\n  File \"D:\\environment\\Anaconda3\\envs\\cv\\Lib\\multiprocessing\\connection.py\", line 329, in _poll\n    return bool(wait([self], timeout))\n                ^^^^^^^^^^^^^^^^^^^^^\n  File \"D:\\environment\\Anaconda3\\envs\\cv\\Lib\\multiprocessing\\connection.py\", line 878, in wait\n    ready_handles = _exhaustive_wait(waithandle_to_obj.keys(), timeout)\n                    ^^^^^^^^^^^^^^^^^^^^^^^^^^^^^^^^^^^^^^^^^^^^^^^^^^^\n  File \"D:\\environment\\Anaconda3\\envs\\cv\\Lib\\multiprocessing\\connection.py\", line 810, in _exhaustive_wait\n    res = _winapi.WaitForMultipleObjects(L, False, timeout)\n          ^^^^^^^^^^^^^^^^^^^^^^^^^^^^^^^^^^^^^^^^^^^^^^^^^\nInterruptedError: [Errno 4] Interrupted function call"}
{"asctime": "[2023-07-05 13:52:29 +0800]", "process": 25592, "levelname": "ERROR", "message": "Experienced exception while trying to serve", "exc_info": "Traceback (most recent call last):\n  File \"D:\\environment\\Anaconda3\\envs\\cv\\Lib\\site-packages\\sanic\\mixins\\startup.py\", line 853, in serve\n    manager.run()\n  File \"D:\\environment\\Anaconda3\\envs\\cv\\Lib\\site-packages\\sanic\\worker\\manager.py\", line 122, in run\n    self.monitor()\n  File \"D:\\environment\\Anaconda3\\envs\\cv\\Lib\\site-packages\\sanic\\worker\\manager.py\", line 183, in monitor\n    self.wait_for_ack()\n  File \"D:\\environment\\Anaconda3\\envs\\cv\\Lib\\site-packages\\sanic\\worker\\manager.py\", line 240, in wait_for_ack\n    if self.monitor_subscriber.poll(0.1):\n       ^^^^^^^^^^^^^^^^^^^^^^^^^^^^^^^^^\n  File \"D:\\environment\\Anaconda3\\envs\\cv\\Lib\\multiprocessing\\connection.py\", line 256, in poll\n    return self._poll(timeout)\n           ^^^^^^^^^^^^^^^^^^^\n  File \"D:\\environment\\Anaconda3\\envs\\cv\\Lib\\multiprocessing\\connection.py\", line 329, in _poll\n    return bool(wait([self], timeout))\n                ^^^^^^^^^^^^^^^^^^^^^\n  File \"D:\\environment\\Anaconda3\\envs\\cv\\Lib\\multiprocessing\\connection.py\", line 878, in wait\n    ready_handles = _exhaustive_wait(waithandle_to_obj.keys(), timeout)\n                    ^^^^^^^^^^^^^^^^^^^^^^^^^^^^^^^^^^^^^^^^^^^^^^^^^^^\n  File \"D:\\environment\\Anaconda3\\envs\\cv\\Lib\\multiprocessing\\connection.py\", line 810, in _exhaustive_wait\n    res = _winapi.WaitForMultipleObjects(L, False, timeout)\n          ^^^^^^^^^^^^^^^^^^^^^^^^^^^^^^^^^^^^^^^^^^^^^^^^^\nInterruptedError: [Errno 4] Interrupted function call"}
{"asctime": "[2023-07-05 13:55:55 +0800]", "process": 27332, "levelname": "ERROR", "message": "Experienced exception while trying to serve", "exc_info": "Traceback (most recent call last):\n  File \"D:\\environment\\Anaconda3\\envs\\cv\\Lib\\site-packages\\sanic\\mixins\\startup.py\", line 853, in serve\n    manager.run()\n  File \"D:\\environment\\Anaconda3\\envs\\cv\\Lib\\site-packages\\sanic\\worker\\manager.py\", line 122, in run\n    self.monitor()\n  File \"D:\\environment\\Anaconda3\\envs\\cv\\Lib\\site-packages\\sanic\\worker\\manager.py\", line 183, in monitor\n    self.wait_for_ack()\n  File \"D:\\environment\\Anaconda3\\envs\\cv\\Lib\\site-packages\\sanic\\worker\\manager.py\", line 240, in wait_for_ack\n    if self.monitor_subscriber.poll(0.1):\n       ^^^^^^^^^^^^^^^^^^^^^^^^^^^^^^^^^\n  File \"D:\\environment\\Anaconda3\\envs\\cv\\Lib\\multiprocessing\\connection.py\", line 256, in poll\n    return self._poll(timeout)\n           ^^^^^^^^^^^^^^^^^^^\n  File \"D:\\environment\\Anaconda3\\envs\\cv\\Lib\\multiprocessing\\connection.py\", line 329, in _poll\n    return bool(wait([self], timeout))\n                ^^^^^^^^^^^^^^^^^^^^^\n  File \"D:\\environment\\Anaconda3\\envs\\cv\\Lib\\multiprocessing\\connection.py\", line 878, in wait\n    ready_handles = _exhaustive_wait(waithandle_to_obj.keys(), timeout)\n                    ^^^^^^^^^^^^^^^^^^^^^^^^^^^^^^^^^^^^^^^^^^^^^^^^^^^\n  File \"D:\\environment\\Anaconda3\\envs\\cv\\Lib\\multiprocessing\\connection.py\", line 810, in _exhaustive_wait\n    res = _winapi.WaitForMultipleObjects(L, False, timeout)\n          ^^^^^^^^^^^^^^^^^^^^^^^^^^^^^^^^^^^^^^^^^^^^^^^^^\nInterruptedError: [Errno 4] Interrupted function call"}
{"asctime": "[2023-07-05 14:41:10 +0800]", "process": 12156, "levelname": "ERROR", "message": "Experienced exception while trying to serve", "exc_info": "Traceback (most recent call last):\n  File \"D:\\environment\\Anaconda3\\envs\\cv\\Lib\\site-packages\\sanic\\mixins\\startup.py\", line 853, in serve\n    manager.run()\n  File \"D:\\environment\\Anaconda3\\envs\\cv\\Lib\\site-packages\\sanic\\worker\\manager.py\", line 122, in run\n    self.monitor()\n  File \"D:\\environment\\Anaconda3\\envs\\cv\\Lib\\site-packages\\sanic\\worker\\manager.py\", line 183, in monitor\n    self.wait_for_ack()\n  File \"D:\\environment\\Anaconda3\\envs\\cv\\Lib\\site-packages\\sanic\\worker\\manager.py\", line 240, in wait_for_ack\n    if self.monitor_subscriber.poll(0.1):\n       ^^^^^^^^^^^^^^^^^^^^^^^^^^^^^^^^^\n  File \"D:\\environment\\Anaconda3\\envs\\cv\\Lib\\multiprocessing\\connection.py\", line 256, in poll\n    return self._poll(timeout)\n           ^^^^^^^^^^^^^^^^^^^\n  File \"D:\\environment\\Anaconda3\\envs\\cv\\Lib\\multiprocessing\\connection.py\", line 329, in _poll\n    return bool(wait([self], timeout))\n                ^^^^^^^^^^^^^^^^^^^^^\n  File \"D:\\environment\\Anaconda3\\envs\\cv\\Lib\\multiprocessing\\connection.py\", line 878, in wait\n    ready_handles = _exhaustive_wait(waithandle_to_obj.keys(), timeout)\n                    ^^^^^^^^^^^^^^^^^^^^^^^^^^^^^^^^^^^^^^^^^^^^^^^^^^^\n  File \"D:\\environment\\Anaconda3\\envs\\cv\\Lib\\multiprocessing\\connection.py\", line 810, in _exhaustive_wait\n    res = _winapi.WaitForMultipleObjects(L, False, timeout)\n          ^^^^^^^^^^^^^^^^^^^^^^^^^^^^^^^^^^^^^^^^^^^^^^^^^\nInterruptedError: [Errno 4] Interrupted function call"}
{"asctime": "[2023-07-05 15:49:32 +0800]", "process": 29888, "levelname": "ERROR", "message": "Experienced exception while trying to serve", "exc_info": "Traceback (most recent call last):\n  File \"D:\\environment\\Anaconda3\\envs\\cv\\Lib\\site-packages\\sanic\\mixins\\startup.py\", line 853, in serve\n    manager.run()\n  File \"D:\\environment\\Anaconda3\\envs\\cv\\Lib\\site-packages\\sanic\\worker\\manager.py\", line 122, in run\n    self.monitor()\n  File \"D:\\environment\\Anaconda3\\envs\\cv\\Lib\\site-packages\\sanic\\worker\\manager.py\", line 183, in monitor\n    self.wait_for_ack()\n  File \"D:\\environment\\Anaconda3\\envs\\cv\\Lib\\site-packages\\sanic\\worker\\manager.py\", line 240, in wait_for_ack\n    if self.monitor_subscriber.poll(0.1):\n       ^^^^^^^^^^^^^^^^^^^^^^^^^^^^^^^^^\n  File \"D:\\environment\\Anaconda3\\envs\\cv\\Lib\\multiprocessing\\connection.py\", line 256, in poll\n    return self._poll(timeout)\n           ^^^^^^^^^^^^^^^^^^^\n  File \"D:\\environment\\Anaconda3\\envs\\cv\\Lib\\multiprocessing\\connection.py\", line 329, in _poll\n    return bool(wait([self], timeout))\n                ^^^^^^^^^^^^^^^^^^^^^\n  File \"D:\\environment\\Anaconda3\\envs\\cv\\Lib\\multiprocessing\\connection.py\", line 878, in wait\n    ready_handles = _exhaustive_wait(waithandle_to_obj.keys(), timeout)\n                    ^^^^^^^^^^^^^^^^^^^^^^^^^^^^^^^^^^^^^^^^^^^^^^^^^^^\n  File \"D:\\environment\\Anaconda3\\envs\\cv\\Lib\\multiprocessing\\connection.py\", line 810, in _exhaustive_wait\n    res = _winapi.WaitForMultipleObjects(L, False, timeout)\n          ^^^^^^^^^^^^^^^^^^^^^^^^^^^^^^^^^^^^^^^^^^^^^^^^^\nInterruptedError: [Errno 4] Interrupted function call"}
{"asctime": "[2023-07-05 19:16:20 +0800]", "process": 29120, "levelname": "ERROR", "message": "Experienced exception while trying to serve", "exc_info": "Traceback (most recent call last):\n  File \"D:\\environment\\Anaconda3\\envs\\cv\\Lib\\site-packages\\sanic\\app.py\", line 1266, in add_task\n    loop = self.loop  # Will raise SanicError if loop is not started\n           ^^^^^^^^^\n  File \"D:\\environment\\Anaconda3\\envs\\cv\\Lib\\site-packages\\sanic\\app.py\", line 258, in loop\n    raise SanicException(\nsanic.exceptions.SanicException: Loop can only be retrieved after the app has started running. Not supported with `create_server` function\n\nDuring handling of the above exception, another exception occurred:\n\nTraceback (most recent call last):\n  File \"D:\\environment\\Anaconda3\\envs\\cv\\Lib\\site-packages\\sanic\\mixins\\startup.py\", line 750, in serve\n    trigger_events(main_start, loop, primary)\n  File \"D:\\environment\\Anaconda3\\envs\\cv\\Lib\\site-packages\\sanic\\server\\events.py\", line 29, in trigger_events\n    loop.run_until_complete(result)\n  File \"D:\\environment\\Anaconda3\\envs\\cv\\Lib\\asyncio\\base_events.py\", line 653, in run_until_complete\n    return future.result()\n           ^^^^^^^^^^^^^^^\n  File \"D:\\Grade 3 Sec\\devops_edge\\edge_service(1).py\", line 221, in main_start\n    edge_app.add_task(heartbeat(), name=\"heartbeat\")\n  File \"D:\\environment\\Anaconda3\\envs\\cv\\Lib\\site-packages\\sanic\\app.py\", line 1276, in add_task\n    raise RuntimeError(\nRuntimeError: Cannot name task outside of a running application"}
{"asctime": "[2023-07-05 19:22:51 +0800]", "process": 35604, "levelname": "ERROR", "message": "Experienced exception while trying to serve", "exc_info": "Traceback (most recent call last):\n  File \"D:\\environment\\Anaconda3\\envs\\cv\\Lib\\site-packages\\sanic\\app.py\", line 1266, in add_task\n    loop = self.loop  # Will raise SanicError if loop is not started\n           ^^^^^^^^^\n  File \"D:\\environment\\Anaconda3\\envs\\cv\\Lib\\site-packages\\sanic\\app.py\", line 258, in loop\n    raise SanicException(\nsanic.exceptions.SanicException: Loop can only be retrieved after the app has started running. Not supported with `create_server` function\n\nDuring handling of the above exception, another exception occurred:\n\nTraceback (most recent call last):\n  File \"D:\\environment\\Anaconda3\\envs\\cv\\Lib\\site-packages\\sanic\\mixins\\startup.py\", line 750, in serve\n    trigger_events(main_start, loop, primary)\n  File \"D:\\environment\\Anaconda3\\envs\\cv\\Lib\\site-packages\\sanic\\server\\events.py\", line 29, in trigger_events\n    loop.run_until_complete(result)\n  File \"D:\\environment\\Anaconda3\\envs\\cv\\Lib\\asyncio\\base_events.py\", line 653, in run_until_complete\n    return future.result()\n           ^^^^^^^^^^^^^^^\n  File \"D:\\Grade 3 Sec\\devops_edge\\edge_service(1).py\", line 221, in main_start\n    edge_app.add_task(heartbeat, name=\"heartbeat\")\n  File \"D:\\environment\\Anaconda3\\envs\\cv\\Lib\\site-packages\\sanic\\app.py\", line 1276, in add_task\n    raise RuntimeError(\nRuntimeError: Cannot name task outside of a running application"}
{"asctime": "[2023-07-05 20:31:42 +0800]", "process": 27908, "levelname": "ERROR", "message": "Exception occurred while handling uri: 'ws://127.0.0.1:82/edge_login'", "exc_info": "Traceback (most recent call last):\n  File \"D:\\environment\\Anaconda3\\envs\\cv\\Lib\\site-packages\\sanic\\app.py\", line 911, in handle_request\n    route, handler, kwargs = self.router.get(\n                             ^^^^^^^^^^^^^^^^\n  File \"D:\\environment\\Anaconda3\\envs\\cv\\Lib\\site-packages\\sanic\\router.py\", line 67, in get\n    return self._get(path, method, host)\n           ^^^^^^^^^^^^^^^^^^^^^^^^^^^^^\n  File \"D:\\environment\\Anaconda3\\envs\\cv\\Lib\\site-packages\\sanic\\router.py\", line 42, in _get\n    raise NotFound(f\"Requested URL {e.path} not found\") from None\nsanic.exceptions.NotFound: Requested URL /edge_login not found\n\nDuring handling of the above exception, another exception occurred:\n\nTraceback (most recent call last):\n  File \"D:\\environment\\Anaconda3\\envs\\cv\\Lib\\site-packages\\sanic\\http\\http1.py\", line 127, in http1\n    await self.protocol.request_handler(self.request)\n  File \"D:\\environment\\Anaconda3\\envs\\cv\\Lib\\site-packages\\sanic\\app.py\", line 1030, in handle_request\n    await self.handle_exception(\n  File \"D:\\environment\\Anaconda3\\envs\\cv\\Lib\\site-packages\\sanic\\app.py\", line 814, in handle_exception\n    response = await self._run_request_middleware(request, middleware)\n               ^^^^^^^^^^^^^^^^^^^^^^^^^^^^^^^^^^^^^^^^^^^^^^^^^^^^^^^\n  File \"D:\\environment\\Anaconda3\\envs\\cv\\Lib\\site-packages\\sanic\\app.py\", line 1118, in _run_request_middleware\n    response = await response\n               ^^^^^^^^^^^^^^\n  File \"d:\\Grade 3 Sec\\devops_edge\\edge_service(1).py\", line 26, in token_auth\nTypeError: string indices must be integers, not 'str'\n\nDuring handling of the above exception, another exception occurred:\n\nTraceback (most recent call last):\n  File \"D:\\environment\\Anaconda3\\envs\\cv\\Lib\\site-packages\\sanic\\http\\http1.py\", line 440, in error_response\n    await app.handle_exception(\n  File \"D:\\environment\\Anaconda3\\envs\\cv\\Lib\\site-packages\\sanic\\app.py\", line 814, in handle_exception\n    response = await self._run_request_middleware(request, middleware)\n               ^^^^^^^^^^^^^^^^^^^^^^^^^^^^^^^^^^^^^^^^^^^^^^^^^^^^^^^\n  File \"D:\\environment\\Anaconda3\\envs\\cv\\Lib\\site-packages\\sanic\\app.py\", line 1118, in _run_request_middleware\n    response = await response\n               ^^^^^^^^^^^^^^\n  File \"d:\\Grade 3 Sec\\devops_edge\\edge_service(1).py\", line 26, in token_auth\nTypeError: string indices must be integers, not 'str'"}
{"asctime": "[2023-07-05 20:32:52 +0800]", "process": 27908, "levelname": "ERROR", "message": "Exception occurred while handling uri: 'ws://127.0.0.1:82/edge_login'", "exc_info": "Traceback (most recent call last):\n  File \"D:\\environment\\Anaconda3\\envs\\cv\\Lib\\site-packages\\sanic\\app.py\", line 911, in handle_request\n    route, handler, kwargs = self.router.get(\n                             ^^^^^^^^^^^^^^^^\n  File \"D:\\environment\\Anaconda3\\envs\\cv\\Lib\\site-packages\\sanic\\router.py\", line 67, in get\n    return self._get(path, method, host)\n           ^^^^^^^^^^^^^^^^^^^^^^^^^^^^^\n  File \"D:\\environment\\Anaconda3\\envs\\cv\\Lib\\site-packages\\sanic\\router.py\", line 42, in _get\n    raise NotFound(f\"Requested URL {e.path} not found\") from None\nsanic.exceptions.NotFound: Requested URL /edge_login not found\n\nDuring handling of the above exception, another exception occurred:\n\nTraceback (most recent call last):\n  File \"D:\\environment\\Anaconda3\\envs\\cv\\Lib\\site-packages\\sanic\\http\\http1.py\", line 127, in http1\n    await self.protocol.request_handler(self.request)\n  File \"D:\\environment\\Anaconda3\\envs\\cv\\Lib\\site-packages\\sanic\\app.py\", line 1030, in handle_request\n    await self.handle_exception(\n  File \"D:\\environment\\Anaconda3\\envs\\cv\\Lib\\site-packages\\sanic\\app.py\", line 814, in handle_exception\n    response = await self._run_request_middleware(request, middleware)\n               ^^^^^^^^^^^^^^^^^^^^^^^^^^^^^^^^^^^^^^^^^^^^^^^^^^^^^^^\n  File \"D:\\environment\\Anaconda3\\envs\\cv\\Lib\\site-packages\\sanic\\app.py\", line 1118, in _run_request_middleware\n    response = await response\n               ^^^^^^^^^^^^^^\n  File \"d:\\Grade 3 Sec\\devops_edge\\edge_service(1).py\", line 26, in token_auth\nTypeError: string indices must be integers, not 'str'\n\nDuring handling of the above exception, another exception occurred:\n\nTraceback (most recent call last):\n  File \"D:\\environment\\Anaconda3\\envs\\cv\\Lib\\site-packages\\sanic\\http\\http1.py\", line 440, in error_response\n    await app.handle_exception(\n  File \"D:\\environment\\Anaconda3\\envs\\cv\\Lib\\site-packages\\sanic\\app.py\", line 814, in handle_exception\n    response = await self._run_request_middleware(request, middleware)\n               ^^^^^^^^^^^^^^^^^^^^^^^^^^^^^^^^^^^^^^^^^^^^^^^^^^^^^^^\n  File \"D:\\environment\\Anaconda3\\envs\\cv\\Lib\\site-packages\\sanic\\app.py\", line 1118, in _run_request_middleware\n    response = await response\n               ^^^^^^^^^^^^^^\n  File \"d:\\Grade 3 Sec\\devops_edge\\edge_service(1).py\", line 26, in token_auth\nTypeError: string indices must be integers, not 'str'"}
{"asctime": "[2023-07-05 20:44:13 +0800]", "process": 27908, "levelname": "ERROR", "message": "Exception occurred while handling uri: 'ws://127.0.0.1:82/edge_login'", "exc_info": "Traceback (most recent call last):\n  File \"D:\\environment\\Anaconda3\\envs\\cv\\Lib\\site-packages\\sanic\\app.py\", line 911, in handle_request\n    route, handler, kwargs = self.router.get(\n                             ^^^^^^^^^^^^^^^^\n  File \"D:\\environment\\Anaconda3\\envs\\cv\\Lib\\site-packages\\sanic\\router.py\", line 67, in get\n    return self._get(path, method, host)\n           ^^^^^^^^^^^^^^^^^^^^^^^^^^^^^\n  File \"D:\\environment\\Anaconda3\\envs\\cv\\Lib\\site-packages\\sanic\\router.py\", line 42, in _get\n    raise NotFound(f\"Requested URL {e.path} not found\") from None\nsanic.exceptions.NotFound: Requested URL /edge_login not found\n\nDuring handling of the above exception, another exception occurred:\n\nTraceback (most recent call last):\n  File \"D:\\environment\\Anaconda3\\envs\\cv\\Lib\\site-packages\\sanic\\http\\http1.py\", line 127, in http1\n    await self.protocol.request_handler(self.request)\n  File \"D:\\environment\\Anaconda3\\envs\\cv\\Lib\\site-packages\\sanic\\app.py\", line 1030, in handle_request\n    await self.handle_exception(\n  File \"D:\\environment\\Anaconda3\\envs\\cv\\Lib\\site-packages\\sanic\\app.py\", line 814, in handle_exception\n    response = await self._run_request_middleware(request, middleware)\n               ^^^^^^^^^^^^^^^^^^^^^^^^^^^^^^^^^^^^^^^^^^^^^^^^^^^^^^^\n  File \"D:\\environment\\Anaconda3\\envs\\cv\\Lib\\site-packages\\sanic\\app.py\", line 1118, in _run_request_middleware\n    response = await response\n               ^^^^^^^^^^^^^^\n  File \"d:\\Grade 3 Sec\\devops_edge\\edge_service(1).py\", line 26, in token_auth\nTypeError: string indices must be integers, not 'str'\n\nDuring handling of the above exception, another exception occurred:\n\nTraceback (most recent call last):\n  File \"D:\\environment\\Anaconda3\\envs\\cv\\Lib\\site-packages\\sanic\\http\\http1.py\", line 440, in error_response\n    await app.handle_exception(\n  File \"D:\\environment\\Anaconda3\\envs\\cv\\Lib\\site-packages\\sanic\\app.py\", line 814, in handle_exception\n    response = await self._run_request_middleware(request, middleware)\n               ^^^^^^^^^^^^^^^^^^^^^^^^^^^^^^^^^^^^^^^^^^^^^^^^^^^^^^^\n  File \"D:\\environment\\Anaconda3\\envs\\cv\\Lib\\site-packages\\sanic\\app.py\", line 1118, in _run_request_middleware\n    response = await response\n               ^^^^^^^^^^^^^^\n  File \"d:\\Grade 3 Sec\\devops_edge\\edge_service(1).py\", line 26, in token_auth\nTypeError: string indices must be integers, not 'str'"}
{"asctime": "[2023-07-05 20:44:51 +0800]", "process": 27908, "levelname": "ERROR", "message": "Exception occurred while handling uri: 'ws://127.0.0.1:82/device_login'", "exc_info": "Traceback (most recent call last):\n  File \"D:\\environment\\Anaconda3\\envs\\cv\\Lib\\site-packages\\sanic\\app.py\", line 948, in handle_request\n    response = await self._run_request_middleware(\n               ^^^^^^^^^^^^^^^^^^^^^^^^^^^^^^^^^^^\n  File \"D:\\environment\\Anaconda3\\envs\\cv\\Lib\\site-packages\\sanic\\app.py\", line 1118, in _run_request_middleware\n    response = await response\n               ^^^^^^^^^^^^^^\n  File \"d:\\Grade 3 Sec\\devops_edge\\edge_service(1).py\", line 26, in token_auth\nTypeError: string indices must be integers, not 'str'"}
{"asctime": "[2023-07-05 20:45:24 +0800]", "process": 27908, "levelname": "ERROR", "message": "Exception occurred while handling uri: 'ws://127.0.0.1:82/device_login'", "exc_info": "Traceback (most recent call last):\n  File \"D:\\environment\\Anaconda3\\envs\\cv\\Lib\\site-packages\\sanic\\app.py\", line 948, in handle_request\n    response = await self._run_request_middleware(\n               ^^^^^^^^^^^^^^^^^^^^^^^^^^^^^^^^^^^\n  File \"D:\\environment\\Anaconda3\\envs\\cv\\Lib\\site-packages\\sanic\\app.py\", line 1118, in _run_request_middleware\n    response = await response\n               ^^^^^^^^^^^^^^\n  File \"d:\\Grade 3 Sec\\devops_edge\\edge_service(1).py\", line 26, in token_auth\nTypeError: string indices must be integers, not 'str'"}
{"asctime": "[2023-07-05 20:47:34 +0800]", "process": 27908, "levelname": "ERROR", "message": "Exception occurred while handling uri: 'ws://127.0.0.1:82/device_login'", "exc_info": "Traceback (most recent call last):\n  File \"D:\\environment\\Anaconda3\\envs\\cv\\Lib\\site-packages\\sanic\\app.py\", line 948, in handle_request\n    response = await self._run_request_middleware(\n               ^^^^^^^^^^^^^^^^^^^^^^^^^^^^^^^^^^^\n  File \"D:\\environment\\Anaconda3\\envs\\cv\\Lib\\site-packages\\sanic\\app.py\", line 1118, in _run_request_middleware\n    response = await response\n               ^^^^^^^^^^^^^^\n  File \"d:\\Grade 3 Sec\\devops_edge\\edge_service(1).py\", line 26, in token_auth\nTypeError: string indices must be integers, not 'str'"}
{"asctime": "[2023-07-05 20:47:49 +0800]", "process": 27908, "levelname": "ERROR", "message": "Exception occurred while handling uri: 'ws://127.0.0.1:82/device_login'", "exc_info": "Traceback (most recent call last):\n  File \"D:\\environment\\Anaconda3\\envs\\cv\\Lib\\site-packages\\sanic\\app.py\", line 948, in handle_request\n    response = await self._run_request_middleware(\n               ^^^^^^^^^^^^^^^^^^^^^^^^^^^^^^^^^^^\n  File \"D:\\environment\\Anaconda3\\envs\\cv\\Lib\\site-packages\\sanic\\app.py\", line 1118, in _run_request_middleware\n    response = await response\n               ^^^^^^^^^^^^^^\n  File \"d:\\Grade 3 Sec\\devops_edge\\edge_service(1).py\", line 26, in token_auth\nTypeError: string indices must be integers, not 'str'"}
{"asctime": "[2023-07-05 20:50:05 +0800]", "process": 27908, "levelname": "ERROR", "message": "Exception occurred while handling uri: 'ws://localhost:82/device_login'", "exc_info": "Traceback (most recent call last):\n  File \"D:\\environment\\Anaconda3\\envs\\cv\\Lib\\site-packages\\sanic\\app.py\", line 948, in handle_request\n    response = await self._run_request_middleware(\n               ^^^^^^^^^^^^^^^^^^^^^^^^^^^^^^^^^^^\n  File \"D:\\environment\\Anaconda3\\envs\\cv\\Lib\\site-packages\\sanic\\app.py\", line 1118, in _run_request_middleware\n    response = await response\n               ^^^^^^^^^^^^^^\n  File \"d:\\Grade 3 Sec\\devops_edge\\edge_service(1).py\", line 26, in token_auth\nTypeError: string indices must be integers, not 'str'"}
{"asctime": "[2023-07-05 20:55:26 +0800]", "process": 27908, "levelname": "ERROR", "message": "Exception occurred while handling uri: 'ws://localhost:82/device_login'", "exc_info": "Traceback (most recent call last):\n  File \"D:\\environment\\Anaconda3\\envs\\cv\\Lib\\site-packages\\sanic\\app.py\", line 948, in handle_request\n    response = await self._run_request_middleware(\n               ^^^^^^^^^^^^^^^^^^^^^^^^^^^^^^^^^^^\n  File \"D:\\environment\\Anaconda3\\envs\\cv\\Lib\\site-packages\\sanic\\app.py\", line 1118, in _run_request_middleware\n    response = await response\n               ^^^^^^^^^^^^^^\n  File \"d:\\Grade 3 Sec\\devops_edge\\edge_service(1).py\", line 26, in token_auth\nTypeError: string indices must be integers, not 'str'"}
{"asctime": "[2023-07-05 20:56:42 +0800]", "process": 27908, "levelname": "ERROR", "message": "Exception occurred while handling uri: 'ws://localhost:82/device_login'", "exc_info": "Traceback (most recent call last):\n  File \"D:\\environment\\Anaconda3\\envs\\cv\\Lib\\site-packages\\sanic\\app.py\", line 948, in handle_request\n    response = await self._run_request_middleware(\n               ^^^^^^^^^^^^^^^^^^^^^^^^^^^^^^^^^^^\n  File \"D:\\environment\\Anaconda3\\envs\\cv\\Lib\\site-packages\\sanic\\app.py\", line 1118, in _run_request_middleware\n    response = await response\n               ^^^^^^^^^^^^^^\n  File \"d:\\Grade 3 Sec\\devops_edge\\edge_service(1).py\", line 26, in token_auth\nTypeError: string indices must be integers, not 'str'"}
{"asctime": "[2023-07-05 20:58:05 +0800]", "process": 27908, "levelname": "ERROR", "message": "Exception occurred while handling uri: 'ws://localhost:82/device_login'", "exc_info": "Traceback (most recent call last):\n  File \"D:\\environment\\Anaconda3\\envs\\cv\\Lib\\site-packages\\sanic\\app.py\", line 948, in handle_request\n    response = await self._run_request_middleware(\n               ^^^^^^^^^^^^^^^^^^^^^^^^^^^^^^^^^^^\n  File \"D:\\environment\\Anaconda3\\envs\\cv\\Lib\\site-packages\\sanic\\app.py\", line 1118, in _run_request_middleware\n    response = await response\n               ^^^^^^^^^^^^^^\n  File \"d:\\Grade 3 Sec\\devops_edge\\edge_service(1).py\", line 26, in token_auth\nTypeError: string indices must be integers, not 'str'"}
{"asctime": "[2023-07-05 21:01:04 +0800]", "process": 27908, "levelname": "ERROR", "message": "Exception occurred while handling uri: 'ws://localhost:82/device_login'", "exc_info": "Traceback (most recent call last):\n  File \"D:\\environment\\Anaconda3\\envs\\cv\\Lib\\site-packages\\sanic\\app.py\", line 948, in handle_request\n    response = await self._run_request_middleware(\n               ^^^^^^^^^^^^^^^^^^^^^^^^^^^^^^^^^^^\n  File \"D:\\environment\\Anaconda3\\envs\\cv\\Lib\\site-packages\\sanic\\app.py\", line 1118, in _run_request_middleware\n    response = await response\n               ^^^^^^^^^^^^^^\n  File \"d:\\Grade 3 Sec\\devops_edge\\edge_service(1).py\", line 26, in token_auth\nTypeError: string indices must be integers, not 'str'"}
