{"asctime": "[2023-07-04 21:37:22 +0800]", "process": 30428, "levelname": "ERROR", "message": "Experienced exception while trying to serve", "exc_info": "Traceback (most recent call last):\n  File \"D:\\environment\\Anaconda3\\envs\\cv\\Lib\\site-packages\\sanic\\mixins\\startup.py\", line 853, in serve\n    manager.run()\n  File \"D:\\environment\\Anaconda3\\envs\\cv\\Lib\\site-packages\\sanic\\worker\\manager.py\", line 122, in run\n    self.monitor()\n  File \"D:\\environment\\Anaconda3\\envs\\cv\\Lib\\site-packages\\sanic\\worker\\manager.py\", line 183, in monitor\n    self.wait_for_ack()\n  File \"D:\\environment\\Anaconda3\\envs\\cv\\Lib\\site-packages\\sanic\\worker\\manager.py\", line 240, in wait_for_ack\n    if self.monitor_subscriber.poll(0.1):\n       ^^^^^^^^^^^^^^^^^^^^^^^^^^^^^^^^^\n  File \"D:\\environment\\Anaconda3\\envs\\cv\\Lib\\multiprocessing\\connection.py\", line 256, in poll\n    return self._poll(timeout)\n           ^^^^^^^^^^^^^^^^^^^\n  File \"D:\\environment\\Anaconda3\\envs\\cv\\Lib\\multiprocessing\\connection.py\", line 329, in _poll\n    return bool(wait([self], timeout))\n                ^^^^^^^^^^^^^^^^^^^^^\n  File \"D:\\environment\\Anaconda3\\envs\\cv\\Lib\\multiprocessing\\connection.py\", line 878, in wait\n    ready_handles = _exhaustive_wait(waithandle_to_obj.keys(), timeout)\n                    ^^^^^^^^^^^^^^^^^^^^^^^^^^^^^^^^^^^^^^^^^^^^^^^^^^^\n  File \"D:\\environment\\Anaconda3\\envs\\cv\\Lib\\multiprocessing\\connection.py\", line 810, in _exhaustive_wait\n    res = _winapi.WaitForMultipleObjects(L, False, timeout)\n          ^^^^^^^^^^^^^^^^^^^^^^^^^^^^^^^^^^^^^^^^^^^^^^^^^\nInterruptedError: [Errno 4] Interrupted function call"}
